INFO:werkzeug:[31m[1mWARNING: This is a development server. Do not use it in a production deployment. Use a production WSGI server instead.[0m
 * Running on all addresses (0.0.0.0)
 * Running on http://127.0.0.1:10000
 * Running on http://172.22.0.4:10000
INFO:werkzeug:[33mPress CTRL+C to quit[0m
INFO:service:None
INFO:service:('4118a827-0fbb-4097-9497-52d3f639652e',)
INFO:werkzeug:172.22.0.1 - - [09/Dec/2023 05:57:08] "POST /login HTTP/1.1" 200 -
INFO:service:('4118a827-0fbb-4097-9497-52d3f639652e',)
INFO:service:WTF???
INFO:service:('4118a827-0fbb-4097-9497-52d3f639652e',)
INFO:service:('4118a827-0fbb-4097-9497-52d3f639652e',)
INFO:service:salt_4118a827-0fbb-4097-9497-52d3f639652e
INFO:service:Nd54kZiomBujcrL6
INFO:service:Nd54kZiomBujcrL6
INFO:werkzeug:172.22.0.1 - - [09/Dec/2023 05:57:12] "GET /confirm HTTP/1.1" 200 -
ERROR:mainloop:Exception on /profile [GET]
Traceback (most recent call last):
  File "/usr/local/lib/python3.9/site-packages/flask/app.py", line 2528, in wsgi_app
    response = self.full_dispatch_request()
  File "/usr/local/lib/python3.9/site-packages/flask/app.py", line 1825, in full_dispatch_request
    rv = self.handle_user_exception(e)
  File "/usr/local/lib/python3.9/site-packages/flask/app.py", line 1823, in full_dispatch_request
    rv = self.dispatch_request()
  File "/usr/local/lib/python3.9/site-packages/flask/app.py", line 1799, in dispatch_request
    return self.ensure_sync(self.view_functions[rule.endpoint])(**view_args)
  File "/app/src/mainloop.py", line 48, in wrapper
    request = args[0]
IndexError: tuple index out of range
INFO:werkzeug:172.22.0.1 - - [09/Dec/2023 05:57:23] "[35m[1mGET /profile HTTP/1.1[0m" 500 -
